<?xml version="1.0"?>
<robot name="trailblazer">
  <!-- Add robot-consistent base_link frame -->
  <link name="base_link" />
  <joint name="baselink_to_tracks" type="fixed">
    <parent link="base_link" />
    <child link="tracks_base_link" />
    <origin rpy="0 0 0" xyz="0 0 0" />
  </joint>
  <!-- Add link representing center of arm workspace -->
  <link name="center_workspace" />
  <joint name="bl_to_center_workspace" type="fixed">
    <parent link="base_link" />
    <child link="center_workspace" />
    <origin rpy="0 0 0" xyz="0.75 0 0" />
  </joint>
  <!-- Fixed joint to add dummy inertia link -->
  <joint name="BL_to_BL_inertia" type="fixed">
    <parent link="base_link" />
    <child link="base_link_inertia" />
    <origin rpy="0 0 0" xyz="0 0 0" />
  </joint>
  <!-- Dummy inertia link, because KDL cannot have inertia on the base link -->
  <link name="base_link_inertia">
    <inertial>
      <mass value="1e-5" />
      <origin rpy="0 0 0" xyz="0 0 0" />
      <inertia ixx="1e-6" ixy="0" ixz="0" iyy="1e-6" iyz="0" izz="1e-6" />
    </inertial>
  </link>
  <link name="tracks_base_link">
    <inertial>
      <origin rpy="0 0 0" xyz="0 0 0.4" />
      <mass value="400" />
      <inertia ixx="30" ixy="0" ixz="0" iyy="30" iyz="0" izz="30" />
    </inertial>
  </link>
  <link name="tracks_compartments">
    <inertial>
      <origin rpy="0 0 0" xyz="0 0 0.4" />
      <mass value="0.1" />
      <inertia ixx="0.001" ixy="0" ixz="0" iyy="0.001" iyz="0" izz="0.001" />
    </inertial>
  </link>
  <!-- Mount to parent -->
  <joint name="tracks_base_link_to_compartments" type="fixed">
    <parent link="tracks_base_link" />
    <child link="tracks_compartments" />
    <origin rpy="0 0 0" xyz="0 0 0" />
  </joint>
  <!-- Base mount of prismatic actuator -->
  <link name="column_base">
    <inertial>
      <mass value="57.3" />
      <origin rpy="0 0 0" xyz="0 0 0.75" />
      <inertia ixx="1e-6" ixy="0" ixz="0" iyy="1e-6" iyz="0" izz="1e-6" />
    </inertial>
  </link>
  <joint name="tracks_base_link_to_column_base" type="fixed">
    <parent link="tracks_base_link" />
    <child link="column_base" />
    <origin rpy="0 0 0" xyz="0.5 0 0.14" />
  </joint>
  <!-- Pseudo joint and link containing the full transform -->
  <link name="column_pseudo_tip">
    <inertial>
      <mass value="1e-5" />
      <origin rpy="0 0 0" xyz="0 0 0" />
      <inertia ixx="1e-6" ixy="0" ixz="0" iyy="1e-6" iyz="0" izz="1e-6" />
    </inertial>
  </link>
  <joint name="column_prismatic_joint" type="prismatic">
    <parent link="column_base" />
    <child link="column_pseudo_tip" />
    <origin rpy="0 0 0" xyz="0 0 0" />
    <axis xyz="0 0 1" />
    <limit effort="1000.0" lower="1.48" upper="3.972" velocity="0.2" />
  </joint>
  <!-- Middle link -->
  <link name="column_middle">
    <inertial>
      <mass value="16.2" />
      <origin rpy="0 0 0" xyz="0 0 -0.75" />
      <inertia ixx="1e-6" ixy="0" ixz="0" iyy="1e-6" iyz="0" izz="1e-6" />
    </inertial>
  </link>
  <joint name="column_middle_joint" type="prismatic">
    <parent link="column_base" />
    <child link="column_middle" />
    <origin rpy="0 0 0" xyz="0 0 0" />
    <axis xyz="0 0 1" />
    <limit effort="1000.0" lower="0.03400000000000003" upper="1.28" velocity="0.1" />
    <mimic joint="column_prismatic_joint" multiplier="0.5" offset="-0.706" />
  </joint>
  <!-- Top link -->
  <link name="column_top">
    <inertial>
      <mass value="14" />
      <origin rpy="0 0 0" xyz="0 0 -0.75" />
      <inertia ixx="1e-6" ixy="0" ixz="0" iyy="1e-6" iyz="0" izz="1e-6" />
    </inertial>
  </link>
  <joint name="column_top_joint" type="prismatic">
    <parent link="column_middle" />
    <child link="column_top" />
    <origin rpy="0 0 0" xyz="0 0 0" />
    <axis xyz="0 0 1" />
    <limit effort="1000.0" lower="0.0040000000000000036" upper="1.25" velocity="0.1" />
    <mimic joint="column_prismatic_joint" multiplier="0.5" offset="-0.736" />
  </joint>
  <!-- Column tip -->
  <link name="column_tip" />
  <joint name="column_top_to_tip" type="fixed">
    <parent link="column_top" />
    <child link="column_tip" />
    <origin rpy="0 0 0" xyz="0 0 1.442" />
  </joint>
  <!-- Top mounting plate -->
  <link name="column_tip_mount">
    <inertial>
      <mass value="6" />
      <origin rpy="0 0 0" xyz="0 0 0" />
      <inertia ixx="1e-6" ixy="0" ixz="0" iyy="1e-6" iyz="0" izz="1e-6" />
    </inertial>
  </link>
  <joint name="column_tip_to_tip_mount" type="fixed">
    <parent link="column_tip" />
    <child link="column_tip_mount" />
    <origin rpy="0 0 0" xyz="0 0 0.076" />
  </joint>
  <!-- Virtual base mount frame for robot arm -->
  <link name="column_tool_mount">
    <inertial>
      <mass value="1e-5" />
      <origin rpy="0 0 0" xyz="0 0 0" />
      <inertia ixx="1e-6" ixy="0" ixz="0" iyy="1e-6" iyz="0" izz="1e-6" />
    </inertial>
  </link>
  <joint name="column_tip_to_tool" type="fixed">
    <parent link="column_tip_mount" />
    <child link="column_tool_mount" />
    <origin rpy="1.570796 0 1.570796" xyz="0.094 0 0" />
  </joint>
  <link name="dsr_base_0">
    <inertial>
      <mass value="4.12" />
      <origin xyz="-3.4e-05   -0.004815    0.048482" />
      <inertia ixx="0.016331" ixy="-6.4837e-06" ixz="2.0048e-06" iyy="0.014945" iyz="-0.00051686"
        izz="0.022577" />
    </inertial>
  </link>
  <!-- joint 1 -->
  <joint name="dsr_joint1" type="revolute">
    <parent link="dsr_base_0" />
    <child link="dsr_link1" />
    <origin rpy="0 0 0" xyz="0 0 0.1525" />
    <axis xyz="0 0 1" />
    <limit effort="346" lower="-6.2832" upper="6.2832" velocity="2.0944" />
    <dynamics friction="0" />
  </joint>
  <link name="dsr_link1">
    <inertial>
      <mass value="7.8" />
      <origin xyz="0.000119      0.0428   -0.006383" />
      <inertia ixx="0.04506" ixy="4.1126e-05" ixz="-5.2533e-05" iyy="0.029679" iyz="-0.0019959"
        izz="0.047056" />
    </inertial>
  </link>
  <!-- joint2 -->
  <joint name="dsr_joint2" type="revolute">
    <parent link="dsr_link1" />
    <child link="dsr_link2" />
    <origin rpy="0 -1.571 -1.571" xyz="0 0.0345 0" />
    <axis xyz="0 0 1" />
    <limit effort="346" lower="-6.2832" upper="6.2832" velocity="2.0944" />
    <dynamics friction="0" />
  </joint>
  <link name="dsr_link2">
    <inertial>
      <mass value="10.83" />
      <origin xyz="0.25973    -5.3e-05     0.15782" />
      <inertia ixx="0.037586" ixy="-0.00036999" ixz="-0.0069927" iyy="0.84943" iyz="4.0201e-05"
        izz="0.85021" />
    </inertial>
  </link>
  <!-- joint3 -->
  <joint name="dsr_joint3" type="revolute">
    <parent link="dsr_link2" />
    <child link="dsr_link3" />
    <origin rpy="0 0 1.571" xyz="0.62 0 0" />
    <axis xyz="0 0 1" />
    <limit effort="163" lower="-2.7925" upper="2.7925" velocity="3.1416" />
    <dynamics friction="0" />
  </joint>
  <link name="dsr_link3">
    <inertial>
      <mass value="3.68" />
      <origin xyz="-1.5e-05   -0.006702    0.044608" />
      <inertia ixx="0.018748" ixy="7.8071e-06" ixz="-5.0324e-06" iyy="0.018972" iyz="-0.00099342"
        izz="0.011502" />
    </inertial>
  </link>
  <!-- joint4 -->
  <joint name="dsr_joint4" type="revolute">
    <parent link="dsr_link3" />
    <child link="dsr_link4" />
    <origin rpy="1.571 0 0" xyz="0 -0.559 0" />
    <axis xyz="0 0 1" />
    <limit effort="50" lower="-6.2832" upper="6.2832" velocity="3.927" />
    <dynamics friction="0" />
  </joint>
  <link name="dsr_link4">
    <inertial>
      <mass value="3.82" />
      <origin xyz="7.1e-05    0.091879    -0.18252" />
      <inertia ixx="0.19063" ixy="-1.8037e-05" ixz="-3.8576e-05" iyy="0.17268" iyz="-0.052996"
        izz="0.030386" />
    </inertial>
  </link>
  <!-- joint5 -->
  <joint name="dsr_joint5" type="revolute">
    <parent link="dsr_link4" />
    <child link="dsr_link5" />
    <origin rpy="-1.571 0 0" xyz="0 0 0" />
    <axis xyz="0 0 1" />
    <limit effort="50" lower="-6.2832" upper="6.2832" velocity="3.927" />
    <dynamics friction="0" />
  </joint>
  <link name="dsr_link5">
    <inertial>
      <mass value="2.82" />
      <origin xyz="-0.000273    0.003651    0.032088" />
      <inertia ixx="0.015583" ixy="2.135e-05" ixz="-5.1895e-06" iyy="0.011519" iyz="0.00042553"
        izz="0.0088671" />
    </inertial>
  </link>
  <!-- joint6 -->
  <joint name="dsr_joint6" type="revolute">
    <parent link="dsr_link5" />
    <child link="dsr_link6" />
    <origin rpy="1.571 0 0" xyz="0 -0.121 0" />
    <axis xyz="0 0 1" />
    <limit effort="50" lower="-6.2832" upper="6.2832" velocity="3.927" />
    <dynamics friction="0" />
  </joint>
  <link name="dsr_link6">
    <inertial>
      <mass value="1.16" />
      <origin xyz="-0.000292       7e-06     -0.0539" />
      <inertia ixx="0.0048282" ixy="4.1298e-06" ixz="6.9879e-06" iyy="0.0059519" iyz="4.252e-06"
        izz="0.0061263" />
    </inertial>
  </link>
  <joint name="column_to_dsr" type="fixed">
    <parent link="column_tool_mount" />
    <child link="dsr_base_0" />
    <origin rpy="0 0 0" xyz="0 0.015 0.01" />
  </joint>
  <joint name="dsr_tool_to_tool" type="fixed">
    <parent link="dsr_link6" />
    <child link="tool_link" />
    <origin rpy="0 0 -1.570796" xyz="0 0 0" />
  </joint>
  <link name="tool_link">
    <inertial>
      <origin rpy="0 0 0" xyz="0 0 0.25" />
      <mass value="3" />
      <inertia ixx="4" ixy="0" ixz="0" iyy="4" iyz="0" izz="4" />
    </inertial>
  </link>
  <link name="drill_tip" />
  <joint name="tool_to_tip" type="fixed">
    <parent link="tool_link" />
    <child link="drill_tip" />
    <origin rpy="0 0 0" xyz="0.00289 -0.00018 0.49926" />
  </joint>

  <link name="prism" />
  <joint name="prism_calib" type="fixed">
    <parent link="tool_link" />
    <child link="prism" />
    <origin rpy="0 0 0" xyz="0.00101828 -0.10091023 0.33565636" />
  </joint>

  <joint name="tilt_sensor_base_joint" type="fixed">
    <parent link="column_base" />
    <child link="tilt_sensor_base" />
    <origin rpy="0 0 0" xyz="-0.04 -0.21 0.30" />
  </joint>
  <link name="tilt_sensor_base" />
  <joint name="tilt_sensor_column_tip_joint" type="fixed">
    <parent link="column_tip" />
    <child link="tilt_sensor_column_tip" />
    <origin rpy="0 0 0" xyz="0.01 0.01 0.15" />
  </joint>
  <link name="tilt_sensor_column_tip" />
</robot>